Workbook
Name Slicer_Department: #N/A
Name Slicer_Performance_Score: #N/A
Name Slicer_Position: #N/A
Name Slicer_Year: #N/A

Sheet Sheet1
A3: Average of Age | B3: Count of Name | C3: Average of Salary | D3: Average of Performance _Score_Range
A4: 35.802616 | B4: 1000 | C4: 60216.086 | D4: 3.017
A6: Key Indicators
A7: Age | B7: 35.802616
A8: Salary | B8: 60216.086
A9: Employees | B9: 1000 | D9: Row Labels | H9: Average of Performance _Score_Range
D10: 2018 | G10: Finance | H10: 2.9495413
D11: 2019 | G11: HR | H11: 2.93
A12: year | B12: average salary | C12: salary growth | D12: 2020 | G12: IT | H12: 3.1502591
A13: 2018 | B13: 59233.129 | D13: Grand Total | G13: Marketing | H13: 3.1764706
A14: 2019 | B14: 60787.781 | C14: =(B14-B13)/B13 -> 0.026246335 | G14: Sales | H14: 2.9009901
A15: 2020 | B15: 60167.131 | C15: =(B15-B14)/B14 -> -0.010210118 | G15: Grand Total | H15: 3.017
A18: Salary Compression | B18: =(B15-B13)/B13 -> 0.015768238 | D18: Row Labels | E18: Average of Salary | G18: Row Labels
D19: Analyst | E19: 60146.199 | G19: A
A20: Row Labels | B20: Average of Salary | D20: Assistant | E20: 59742.857 | G20: B
A21: Finance | B21: 59971.591 | D21: Clerk | E21: 60029.762 | G21: C
A22: HR | B22: 60261.628 | D22: Director | E22: 60920.245 | G22: D
A23: IT | B23: 59756.098 | D23: Manager | E23: 60288.462 | G23: F
A24: Marketing | B24: 60065.359 | D24: Grand Total | E24: 60216.086 | G24: Grand Total | H24: Row Labels | I24: Average of Salary
A25: Sales | B25: 61011.905 | H25: Finance | I25: 59971.591
A26: Grand Total | B26: 60216.086 | D26: Row Labels | E26: Count of Name | H26: HR | I26: 60261.628
D27: A | E27: 193 | H27: IT | I27: 59756.098
D28: B | E28: 225 | H28: Marketing | I28: 60065.359
A29: Row Labels | B29: Count of Name | D29: C | E29: 192 | H29: Sales | I29: 61011.905
A30: Female | B30: 313 | D30: D | E30: 189 | H30: Grand Total | I30: 60216.086
A31: Male | B31: 355 | D31: F | E31: 201
A32: Other | B32: 332 | D32: Grand Total | E32: 1000
A33: Grand Total | B33: 1000 | F33: Row Labels | G33: Average of Salary | I33: Row Labels | J33: Average of Salary
F34: 1 | G34: 60327.381 | I34: A | J34: 60156.25
A35: Row Labels | F35: 2 | G35: 60090.909 | I35: B | J35: 60638.298
A36: 25 | F36: 3 | G36: 59705.882 | I36: C | J36: 59705.882
A37: 30 | F37: 4 | G37: 60638.298 | I37: D | J37: 60152.439
A38: 35 | F38: 5 | G38: 60220.126 | I38: F | J38: 60327.381
A39: 40 | F39: Grand Total | G39: 60216.086 | I39: Grand Total | J39: 60216.086
A40: 50
A42: Grand Total
C43: Row Labels | D43: Average of Performance _Score_Range | F43: Row Labels | G43: Average of Salary
C44: 2018 | D44: 3.0053763 | F44: 2018 | G44: 59233.129
C45: 2019 | D45: 2.9766234 | F45: 2019 | G45: 60787.781
C46: 2020 | D46: 3.0582751 | F46: 2020 | G46: 60167.131
...

Sheet Dashboard

Sheet messy_HR_data_Cleaned
A1: Name | B1: Age | C1: Salary | D1: Gender | E1: Department | F1: Position | G1: Year | H1: Joining Date | I1: Month | J1: Performance Score | K1: Performance _Score_Range | L1: Salary Performance
A2: Grace | B2: 25 | C2: 50000 | D2: Male | E2: HR | F2: Manager | G2: 2018 | H2: 43195 | I2: April | J2: D | K2: 2 | L2: =IF(AND(C2> Sheet1!B8,K2<3), "Misaligned","Aligned") -> Aligned
A3: David | C3: 65000 | D3: Female | E3: Finance | F3: Director | G3: 2020 | H3: 43881 | I3: February | J3: F | K3: 1 | L3: =IF(AND(C3> Sheet1!B9,K3<3), "Misaligned","Aligned") -> Misaligned
A4: Hannah | B4: 35 | C4: 60000 | D4: Female | E4: Sales | F4: Director | G4: 2020 | H4: 43845 | I4: January | J4: C | K4: 3 | L4: =IF(AND(C4> Sheet1!B10,K4<3), "Misaligned","Aligned") -> Aligned
A5: Eve | C5: 50000 | D5: Female | E5: IT | F5: Manager | G5: 2018 | H5: 43195 | I5: April | J5: A | K5: 5 | L5: =IF(AND(C5> Sheet1!B11,K5<3), "Misaligned","Aligned") -> Aligned
A6: Grace | D6: Female | E6: Finance | F6: Manager | G6: 2020 | H6: 43845 | I6: January | J6: F | K6: 1 | L6: =IF(AND(C6> Sheet1!B12,K6<3), "Misaligned","Aligned") -> Aligned
A7: Jack | C7: 65000 | D7: Other | E7: Marketing | F7: Director | G7: 2019 | H7: 43549 | I7: March | J7: F | K7: 1 | L7: =IF(AND(C7> Sheet1!B13,K7<3), "Misaligned","Aligned") -> Misaligned
A8: Charlie | C8: 50000 | D8: Male | E8: Marketing | F8: Clerk | G8: 2019 | H8: 43800 | I8: December | J8: B | K8: 4 | L8: =IF(AND(C8> Sheet1!B14,K8<3), "Misaligned","Aligned") -> Aligned
A9: Grace | B9: 40 | C9: 50000 | D9: Other | E9: HR | F9: Director | G9: 2019 | H9: 43549 | I9: March | J9: C | K9: 3 | L9: =IF(AND(C9> Sheet1!B15,K9<3), "Misaligned","Aligned") -> Aligned
A10: Hannah | B10: 40 | C10: 60000 | D10: Female | E10: Marketing | F10: Manager | G10: 2020 | H10: 43845 | I10: January | J10: C | K10: 3 | L10: =IF(AND(C10> Sheet1!B16,K10<3), "Misaligned","Aligned") -> Aligned
A11: Eve | B11: 30 | D11: Other | E11: Finance | F11: Assistant | G11: 2020 | H11: 43881 | I11: February | J11: A | K11: 5 | L11: =IF(AND(C11> Sheet1!B17,K11<3), "Misaligned","Aligned") -> Aligned
A12: David | B12: 25 | C12: 70000 | D12: Male | E12: Marketing | F12: Analyst | G12: 2019 | H12: 43800 | I12: December | J12: B | K12: 4 | L12: =IF(AND(C12> Sheet1!B18,K12<3), "Misaligned","Aligned") -> Aligned
A13: Hannah | C13: 70000 | D13: Other | E13: Finance | F13: Assistant | G13: 2019 | H13: 43549 | I13: March | J13: A | K13: 5 | L13: =IF(AND(C13> Sheet1!B19,K13<3), "Misaligned","Aligned") -> Aligned
A14: Hannah | B14: 30 | C14: 50000 | D14: Male | E14: IT | F14: Assistant | G14: 2018 | H14: 43195 | I14: April | J14: D | K14: 2 | L14: =IF(AND(C14> Sheet1!B20,K14<3), "Misaligned","Aligned") -> Aligned
A15: Charlie | B15: 25 | C15: 55000 | D15: Other | E15: HR | F15: Manager | G15: 2020 | H15: 43881 | I15: February | J15: F | K15: 1 | L15: =IF(AND(C15> Sheet1!B21,K15<3), "Misaligned","Aligned") -> Aligned
A16: Frank | B16: 50 | D16: Male | E16: Marketing | F16: Director | G16: 2019 | H16: 43549 | I16: March | J16: A | K16: 5 | L16: =IF(AND(C16> Sheet1!B22,K16<3), "Misaligned","Aligned") -> Aligned
A17: Eve | B17: 35 | C17: 65000 | D17: Male | E17: Finance | F17: Clerk | G17: 2018 | H17: 43195 | I17: April | J17: F | K17: 1 | L17: =IF(AND(C17> Sheet1!B23,K17<3), "Misaligned","Aligned") -> Misaligned
A18: Bob | B18: 40 | C18: 55000 | D18: Female | E18: Sales | F18: Assistant | G18: 2020 | H18: 43845 | I18: January | J18: B | K18: 4 | L18: =IF(AND(C18> Sheet1!B24,K18<3), "Misaligned","Aligned") -> Aligned
A19: Hannah | B19: 50 | C19: 55000 | D19: Male | E19: HR | F19: Director | G19: 2018 | H19: 43195 | I19: April | J19: D | K19: 2 | L19: =IF(AND(C19> Sheet1!B25,K19<3), "Misaligned","Aligned") -> Aligned
A20: Frank | B20: 25 | D20: Female | E20: IT | F20: Clerk | G20: 2019 | H20: 43549 | I20: March | J20: B | K20: 4 | L20: =IF(AND(C20> Sheet1!B26,K20<3), "Misaligned","Aligned") -> Aligned
A21: Bob | B21: 50 | C21: 50000 | D21: Female | E21: Finance | F21: Assistant | G21: 2019 | H21: 43549 | I21: March | J21: A | K21: 2 | L21: =IF(AND(C21> Sheet1!B27,K21<3), "Misaligned","Aligned") -> Misaligned
A22: Eve | B22: 35 | C22: 50000 | D22: Female | E22: IT | F22: Clerk | G22: 2020 | H22: 43845 | I22: January | J22: D | K22: 2 | L22: =IF(AND(C22> Sheet1!B28,K22<3), "Misaligned","Aligned") -> Misaligned
A23: Alice | B23: 25 | C23: 50000 | D23: Other | E23: IT | F23: Director | G23: 2018 | H23: 43195 | I23: April | J23: F | K23: 1 | L23: =IF(AND(C23> Sheet1!B29,K23<3), "Misaligned","Aligned") -> Aligned
A24: Jack | B24: 50 | C24: 50000 | D24: Other | E24: Marketing | F24: Analyst | G24: 2018 | H24: 43195 | I24: April | J24: B | K24: 4 | L24: =IF(AND(C24> Sheet1!B30,K24<3), "Misaligned","Aligned") -> Aligned
A25: Frank | B25: 40 | C25: 70000 | D25: Other | E25: Marketing | F25: Director | G25: 2020 | H25: 43845 | I25: January | J25: B | K25: 4 | L25: =IF(AND(C25> Sheet1!B31,K25<3), "Misaligned","Aligned") -> Aligned
A26: Ivy | B26: 40 | C26: 50000 | D26: Other | E26: Finance | F26: Manager | G26: 2018 | H26: 43195 | I26: April | J26: A | K26: 5 | L26: =IF(AND(C26> Sheet1!B32,K26<3), "Misaligned","Aligned") -> Aligned
A27: Alice | B27: 30 | C27: 70000 | D27: Male | E27: Sales | F27: Clerk | G27: 2020 | H27: 43845 | I27: January | J27: B | K27: 4 | L27: =IF(AND(C27> Sheet1!B33,K27<3), "Misaligned","Aligned") -> Aligned
A28: Jack | B28: 50 | C28: 70000 | D28: Male | E28: Finance | F28: Analyst | G28: 2020 | H28: 43881 | I28: February | J28: A | K28: 5 | L28: =IF(AND(C28> Sheet1!B34,K28<3), "Misaligned","Aligned") -> Aligned
A29: Charlie | C29: 50000 | D29: Other | E29: Sales | F29: Clerk | G29: 2019 | H29: 43549 | I29: March | J29: C | K29: 3 | L29: =IF(AND(C29> Sheet1!B35,K29<3), "Misaligned","Aligned") -> Aligned
A30: Grace | B30: 50 | C30: 60000 | D30: Male | E30: IT | F30: Clerk | G30: 2020 | H30: 43881 | I30: February | J30: C | K30: 3 | L30: =IF(AND(C30> Sheet1!B36,K30<3), "Misaligned","Aligned") -> Aligned
A31: David | B31: 25 | C31: 65000 | D31: Male | E31: HR | F31: Assistant | G31: 2019 | H31: 43800 | I31: December | J31: C | K31: 3 | L31: =IF(AND(C31> Sheet1!B37,K31<3), "Misaligned","Aligned") -> Aligned
A32: Ivy | B32: 25 | C32: 55000 | D32: Female | E32: Finance | F32: Manager | G32: 2019 | H32: 43800 | I32: December | J32: B | K32: 4 | L32: =IF(AND(C32> Sheet1!B38,K32<3), "Misaligned","Aligned") -> Aligned
A33: Charlie | B33: 50 | C33: 70000 | D33: Female | E33: Finance | F33: Clerk | G33: 2019 | H33: 43800 | I33: December | J33: B | K33: 4 | L33: =IF(AND(C33> Sheet1!B39,K33<3), "Misaligned","Aligned") -> Aligned
A34: Eve | B34: 35 | D34: Female | E34: Sales | F34: Director | G34: 2020 | H34: 43845 | I34: January | J34: A | K34: 5 | L34: =IF(AND(C34> Sheet1!B40,K34<3), "Misaligned","Aligned") -> Aligned
A35: Charlie | B35: 40 | D35: Female | E35: IT | F35: Director | G35: 2018 | H35: 43195 | I35: April | J35: D | K35: 2 | L35: =IF(AND(C35> Sheet1!B41,K35<3), "Misaligned","Aligned") -> Misaligned
A36: Grace | B36: 25 | C36: 65000 | D36: Male | E36: IT | F36: Assistant | G36: 2020 | H36: 43881 | I36: February | J36: A | K36: 5 | L36: =IF(AND(C36> Sheet1!B42,K36<3), "Misaligned","Aligned") -> Aligned
A37: Eve | B37: 40 | D37: Other | E37: Sales | F37: Manager | G37: 2020 | H37: 43881 | I37: February | J37: C | K37: 3 | L37: =IF(AND(C37> Sheet1!B43,K37<3), "Misaligned","Aligned") -> Aligned
A38: Ivy | B38: 25 | C38: 60000 | D38: Male | E38: IT | F38: Manager | G38: 2020 | H38: 43881 | I38: February | J38: A | K38: 5 | L38: =IF(AND(C38> Sheet1!B44,K38<3), "Misaligned","Aligned") -> Aligned
A39: Grace | B39: 30 | D39: Male | E39: Marketing | F39: Director | G39: 2020 | H39: 43881 | I39: February | J39: D | K39: 2 | L39: =IF(AND(C39> Sheet1!B45,K39<3), "Misaligned","Aligned") -> Misaligned
A40: Bob | C40: 55000 | D40: Male | E40: HR | F40: Analyst | G40: 2019 | H40: 43800 | I40: December | J40: B | K40: 4 | L40: =IF(AND(C40> Sheet1!B46,K40<3), "Misaligned","Aligned") -> Aligned
...
